[2023-08-08T15:07:46.851+0000] {taskinstance.py:1103} INFO - Dependencies all met for dep_context=non-requeueable deps ti=<TaskInstance: dag_python_operator_v4.python_task_01 manual__2023-08-08T15:07:39.592063+00:00 [queued]>
[2023-08-08T15:07:46.884+0000] {taskinstance.py:1103} INFO - Dependencies all met for dep_context=requeueable deps ti=<TaskInstance: dag_python_operator_v4.python_task_01 manual__2023-08-08T15:07:39.592063+00:00 [queued]>
[2023-08-08T15:07:46.887+0000] {taskinstance.py:1308} INFO - Starting attempt 1 of 6
[2023-08-08T15:07:46.945+0000] {taskinstance.py:1327} INFO - Executing <Task(PythonOperator): python_task_01> on 2023-08-08 15:07:39.592063+00:00
[2023-08-08T15:07:46.975+0000] {standard_task_runner.py:57} INFO - Started process 1286 to run task
[2023-08-08T15:07:47.008+0000] {standard_task_runner.py:84} INFO - Running: ['***', 'tasks', 'run', 'dag_python_operator_v4', 'python_task_01', 'manual__2023-08-08T15:07:39.592063+00:00', '--job-id', '10', '--raw', '--subdir', 'DAGS_FOLDER/dag_python_op.py', '--cfg-path', '/tmp/tmp3vpal23u']
[2023-08-08T15:07:47.034+0000] {standard_task_runner.py:85} INFO - Job 10: Subtask python_task_01
[2023-08-08T15:07:47.195+0000] {task_command.py:410} INFO - Running <TaskInstance: dag_python_operator_v4.python_task_01 manual__2023-08-08T15:07:39.592063+00:00 [running]> on host 9d880a75227b
[2023-08-08T15:07:47.533+0000] {taskinstance.py:1547} INFO - Exporting env vars: AIRFLOW_CTX_DAG_OWNER='Felipe' AIRFLOW_CTX_DAG_ID='dag_python_operator_v4' AIRFLOW_CTX_TASK_ID='python_task_01' AIRFLOW_CTX_EXECUTION_DATE='2023-08-08T15:07:39.592063+00:00' AIRFLOW_CTX_TRY_NUMBER='1' AIRFLOW_CTX_DAG_RUN_ID='manual__2023-08-08T15:07:39.592063+00:00'
[2023-08-08T15:07:47.538+0000] {logging_mixin.py:150} INFO - TYPE: -----> <class '***.models.taskinstance.TaskInstance'>
[2023-08-08T15:07:47.541+0000] {taskinstance.py:1824} ERROR - Task failed with exception
Traceback (most recent call last):
  File "/home/airflow/.local/lib/python3.7/site-packages/airflow/operators/python.py", line 181, in execute
    return_value = self.execute_callable()
  File "/home/airflow/.local/lib/python3.7/site-packages/airflow/operators/python.py", line 198, in execute_callable
    return self.python_callable(*self.op_args, **self.op_kwargs)
  File "/opt/airflow/dags/dag_python_op.py", line 17, in greed
    f"Hello, my name is {ti.xcoms_pull(task_ids='return_name')} and I am {age} years old!"
AttributeError: 'TaskInstance' object has no attribute 'xcoms_pull'
[2023-08-08T15:07:47.569+0000] {taskinstance.py:1350} INFO - Marking task as UP_FOR_RETRY. dag_id=dag_python_operator_v4, task_id=python_task_01, execution_date=20230808T150739, start_date=20230808T150746, end_date=20230808T150747
[2023-08-08T15:07:47.600+0000] {standard_task_runner.py:109} ERROR - Failed to execute job 10 for task python_task_01 ('TaskInstance' object has no attribute 'xcoms_pull'; 1286)
[2023-08-08T15:07:47.640+0000] {local_task_job_runner.py:225} INFO - Task exited with return code 1
[2023-08-08T15:07:47.683+0000] {taskinstance.py:2653} INFO - 0 downstream tasks scheduled from follow-on schedule check
